<?xml version="1.0" ?>
<robot name="kr270">

<joint name="joint_base" type="fixed">
  <parent link="world"/>
  <child link="socket"/>
</joint>

  <joint name="joint_a1" type="revolute">
    <parent link="socket"/>
    <child link="a1"/>
    <origin rpy="0  0  0" xyz="0    0    0.25"/>
    <axis xyz="0  0  1"/>
    <limit effort="0.0" lower="-3.2289" upper="3.2289" velocity="0.0"/>
  </joint>
  <!--
  <joint name="collision_KR270__joint_a2" type="revolute">
    <parent link="collision_KR270__a1"/>
    <child link="collision_KR270__a2"/>
    <origin rpy="0  0  0" xyz="-0.35  0.3   0.4"/>
    <axis xyz="0  1  0"/>
    <limit effort="0.0" lower="-1.484" upper="0.873" velocity="0.0"/>
  </joint>
  
  <joint name="collision_KR270__joint_a3" type="revolute">
    <parent link="collision_KR270__a2"/>
    <child link="collision_KR270__a3"/>
    <origin rpy="0  0  0" xyz="0      -0.3      1.14999"/>
    <axis xyz="0  1  0"/>
    <limit effort="0.0" lower="-1.1345" upper="3.665" velocity="0.0"/>
  </joint>
  
  <joint name="collision_KR270__joint_a4" type="revolute">
    <parent link="collision_KR270__a3"/>
    <child link="collision_KR270__a4"/>
    <origin rpy="0  0  0" xyz="-1.02499  0       0"/>
    <axis xyz="1  0  0"/>
    <limit effort="0.0" lower="-6.109" upper="6.109" velocity="0.0"/>
  </joint>
  
  <joint name="collision_KR270__joint_a5" type="revolute">
    <parent link="collision_KR270__a4"/>
    <child link="collision_KR270__a5"/>
    <origin rpy="0  0  0" xyz="-0.175  0     0.025"/>
    <axis xyz="0  1  0"/>
    <limit effort="0.0" lower="-2.138" upper="2.138" velocity="0.0"/>
  </joint>
  -->
  <link name="world"/>
  
  <link name="socket">
  
    <inertial>
      <mass value="0"/>
      <origin rpy="0  0  0" xyz="0   0   0.1"/>
      <inertia ixx="0" ixy="0" ixz="0" iyy="0" iyz="0" izz="0"/>
    </inertial>
    <collision name="collision_1">
      <origin rpy="0  0  0" xyz="0   0   0.1"/>
      <geometry>
        <box size=".7 .7 .2"/>
      </geometry>
    </collision>
    
    <visual name="visual_collision_1">
      <origin rpy="0  0  0" xyz="0   0   0.1"/>
      <geometry>
        <box size=".7 .7 .2"/>
      </geometry>
    </visual>
  </link>
  
  <link name="a1">
    <inertial>
      <mass value="0"/>
      <origin rpy="0  0  0" xyz="0   0   0.2"/>
      <inertia ixx="0" ixy="0" ixz="0" iyy="0" iyz="0" izz="0"/>
    </inertial>
    <collision name="collision_1">
      <origin rpy="0  0  0" xyz="0   0   0.2"/>
      <geometry>
        <cylinder length=".4" radius=".225"/>
      </geometry>
    </collision>
    <visual name="visual_collision_1">
      <origin rpy="0  0  0" xyz="0   0   0.2"/>
      <geometry>
        <cylinder length=".4" radius=".225"/>
      </geometry>
    </visual>
  </link>
  <!--
  <link name="collision_KR270__a2">
    <inertial>
      <mass value="0"/>
      <origin rpy="0  0  0" xyz="0   0   0.7"/>
      <inertia ixx="0" ixy="0" ixz="0" iyy="0" iyz="0" izz="0"/>
    </inertial>
    <collision name="collision_KR270__collision_1">
      <origin rpy="0  0  0" xyz="0   0   0.7"/>
      <geometry>
        <box size=".3 .3 1.3"/>
      </geometry>
    </collision>
    <visual name="collision_KR270__visual_collision_1">
      <origin rpy="0  0  0" xyz="0   0   0.7"/>
      <geometry>
        <box size=".3 .3 1.3"/>
      </geometry>
    </visual>
  </link>
  
  <link name="collision_KR270__a3">
    <inertial>
      <mass value="0"/>
      <origin rpy="0  0  0" xyz="-0.15  0    0"/>
      <inertia ixx="0" ixy="0" ixz="0" iyy="0" iyz="0" izz="0"/>
    </inertial>
    <collision name="collision_KR270__collision_1">
      <origin rpy="0      1.5707  0" xyz="-0.15  0    0"/>
      <geometry>
        <cylinder length="1.2" radius="0.15"/>
      </geometry>
    </collision>
    <visual name="collision_KR270__visual_collision_1">
      <origin rpy="0      1.5707  0" xyz="-0.15  0    0"/>
      <geometry>
        <cylinder length="1.2" radius="0.15"/>
      </geometry>
    </visual>
  </link>
  
  <link name="collision_KR270__a4">
    <inertial>
      <mass value="0"/>
      <origin rpy="0  0  0" xyz="0  0  0"/>
      <inertia ixx="0" ixy="0" ixz="0" iyy="0" iyz="0" izz="0"/>
    </inertial>
    <collision name="collision_KR270__collision">
      <origin rpy="0      1.5707  0" xyz="0     0     0.025"/>
      <geometry>
        <cylinder length="0.5" radius="0.1"/>
      </geometry>
    </collision>
    <visual name="collision_KR270__visual_collision">
      <origin rpy="0      1.5707  0" xyz="0     0     0.025"/>
      <geometry>
        <cylinder length="0.5" radius="0.1"/>
      </geometry>
    </visual>
  </link>
  
  <link name="collision_KR270__a5">
    <inertial>
      <mass value="0"/>
      <origin rpy="0  0  0" xyz="0  0  0"/>
      <inertia ixx="0" ixy="0" ixz="0" iyy="0" iyz="0" izz="0"/>
    </inertial>
    <collision name="collision_KR270__collision_1">
      <origin rpy="1.5707  0      0" xyz="0    -0.02  -0.025"/>
      <geometry>
        <cylinder length="0.3" radius="0.125"/>
      </geometry>
    </collision>
    <visual name="collision_KR270__visual_collision_1">
      <origin rpy="1.5707  0      0" xyz="0    -0.02  -0.025"/>
      <geometry>
        <cylinder length="0.3" radius="0.125"/>
      </geometry>
    </visual>
  </link>
  -->
</robot>
